<?xml version="1.0" encoding="utf-8"?>
<robot
  name="panda"
  xmlns:xacro="http://ros.org/wiki/xacro">

  <!-- world -->
  <link name="world"/>
  <joint name="connect_root_and_world" type="fixed">
    <child link="panda_link0" />
    <parent link="world" />
    <origin xyz="0 0 0" rpy="0 0 0" />    
  </joint> 

  <!-- arm -->
  <!-- links and joints -->
  <link name="panda_link0">
      <visual>
          <geometry>
              <mesh filename="file://$(find panda_description)/meshes/visual/link0.dae" />
          </geometry>
      </visual>
      <collision>
          <geometry>
              <mesh filename="file://$(find panda_description)/meshes/collision/link0.stl" />
          </geometry>
      </collision>
    <inertial>
    <origin xyz="0 0 0.32"/>
    <mass value="50"/> 
    <inertia ixx="0.2" ixy="0" ixz="0" iyy="0.2" iyz="0" izz="0.4" />
    </inertial>
  </link>
  <link name="panda_link1">
      <visual>
          <geometry>
              <mesh filename="file://$(find panda_description)/meshes/visual/link1.dae" />
          </geometry>
      </visual>
      <collision>
          <geometry>
              <mesh filename="file://$(find panda_description)/meshes/collision/link1.stl" />
          </geometry>
      </collision>
    <inertial>
    <origin xyz="0 0 0.32"/>
    <mass value="0.5"/> 
    <inertia ixx="0.002" ixy="0" ixz="0" iyy="0.002" iyz="0" izz="0.002" />
    </inertial>
  </link>
  <joint name="panda_joint1" type="revolute">
      <safety_controller k_position="100.0" k_velocity="40.0" soft_lower_limit="-2.8973" soft_upper_limit="2.8973" />
      <origin rpy="0 0 0" xyz="0 0 0.333" />
      <parent link="panda_link0" />
      <child link="panda_link1" />
      <axis xyz="0 0 1" />
      <limit effort="87" lower="-2.9671" upper="2.9671" velocity="2.3925" />
  </joint>
  <link name="panda_link2">
      <visual>
          <geometry>
              <mesh filename="file://$(find panda_description)/meshes/visual/link2.dae" />
          </geometry>
      </visual>
      <collision>
          <geometry>
              <mesh filename="file://$(find panda_description)/meshes/collision/link2.stl" />
          </geometry>
      </collision>
    <inertial>
    <origin xyz="0 0 0.32"/>
    <mass value="0.5"/> 
    <inertia ixx="0.002" ixy="0" ixz="0" iyy="0.002" iyz="0" izz="0.002" />
    </inertial>
  </link>
  <joint name="panda_joint2" type="revolute">
      <safety_controller k_position="100.0" k_velocity="40.0" soft_lower_limit="-1.7628" soft_upper_limit="1.7628" />
      <origin rpy="-1.57079632679 0 0" xyz="0 0 0" />
      <parent link="panda_link1" />
      <child link="panda_link2" />
      <axis xyz="0 0 1" />
      <limit effort="87" lower="-1.8326" upper="1.8326" velocity="2.3925" />
  </joint>
  <link name="panda_link3">
      <visual>
          <geometry>
              <mesh filename="file://$(find panda_description)/meshes/visual/link3.dae" />
          </geometry>
      </visual>
      <collision>
          <geometry>
              <mesh filename="file://$(find panda_description)/meshes/collision/link3.stl" />
          </geometry>
      </collision>
    <inertial>
    <origin xyz="0 0 0.32"/>
    <mass value="0.5"/> 
    <inertia ixx="0.002" ixy="0" ixz="0" iyy="0.002" iyz="0" izz="0.002" />
    </inertial>
  </link>
  <joint name="panda_joint3" type="revolute">
      <safety_controller k_position="100.0" k_velocity="40.0" soft_lower_limit="-2.8973" soft_upper_limit="2.8973" />
      <origin rpy="1.57079632679 0 0" xyz="0 -0.316 0" />
      <parent link="panda_link2" />
      <child link="panda_link3" />
      <axis xyz="0 0 1" />
      <limit effort="87" lower="-2.9671" upper="2.9671" velocity="2.3925" />
  </joint>
  <link name="panda_link4">
      <visual>
          <geometry>
              <mesh filename="file://$(find panda_description)/meshes/visual/link4.dae" />
          </geometry>
      </visual>
      <collision>
          <geometry>
              <mesh filename="file://$(find panda_description)/meshes/collision/link4.stl" />
          </geometry>
      </collision>
    <inertial>
    <origin xyz="0 0 0.32"/>
    <mass value="0.5"/> 
    <inertia ixx="0.002" ixy="0" ixz="0" iyy="0.002" iyz="0" izz="0.002" />
    </inertial>
  </link>
  <joint name="panda_joint4" type="revolute">
      <safety_controller k_position="100.0" k_velocity="40.0" soft_lower_limit="-3.0718" soft_upper_limit="0.0175" />
      <origin rpy="1.57079632679 0 0" xyz="0.0825 0 0" />
      <parent link="panda_link3" />
      <child link="panda_link4" />
      <axis xyz="0 0 1" />
      <limit effort="87" lower="-3.1416" upper="0.0873" velocity="2.3925" />
  </joint>
  <link name="panda_link5">
      <visual>
          <geometry>
              <mesh filename="file://$(find panda_description)/meshes/visual/link5.dae" />
          </geometry>
      </visual>
      <collision>
          <geometry>
              <mesh filename="file://$(find panda_description)/meshes/collision/link5.stl" />
          </geometry>
      </collision>
    <inertial>
    <origin xyz="0 0 0.32"/>
    <mass value="0.5"/> 
    <inertia ixx="0.002" ixy="0" ixz="0" iyy="0.002" iyz="0" izz="0.002" />
    </inertial>
  </link>
  <joint name="panda_joint5" type="revolute">
      <safety_controller k_position="100.0" k_velocity="40.0" soft_lower_limit="-2.8973" soft_upper_limit="2.8973" />
      <origin rpy="-1.57079632679 0 0" xyz="-0.0825 0.384 0" />
      <parent link="panda_link4" />
      <child link="panda_link5" />
      <axis xyz="0 0 1" />
      <limit effort="12" lower="-2.9671" upper="2.9671" velocity="2.8710" />
  </joint>
  <link name="panda_link6">
      <visual>
          <geometry>
              <mesh filename="file://$(find panda_description)/meshes/visual/link6.dae" />
          </geometry>
      </visual>
      <collision>
          <geometry>
              <mesh filename="file://$(find panda_description)/meshes/collision/link6.stl" />
          </geometry>
      </collision>
    <inertial>
    <origin xyz="0 0 0.32"/>
    <mass value="0.5"/> 
    <inertia ixx="0.002" ixy="0" ixz="0" iyy="0.002" iyz="0" izz="0.002" />
    </inertial>
  </link>
  <joint name="panda_joint6" type="revolute">
      <safety_controller k_position="100.0" k_velocity="40.0" soft_lower_limit="-0.0175" soft_upper_limit="3.7525" />
      <origin rpy="1.57079632679 0 0" xyz="0 0 0" />
      <parent link="panda_link5" />
      <child link="panda_link6" />
      <axis xyz="0 0 1" />
      <limit effort="12" lower="-0.0873" upper="3.8223" velocity="2.8710" />
  </joint>
  <link name="panda_link7">
      <visual>
          <geometry>
              <mesh filename="file://$(find panda_description)/meshes/visual/link7.dae" />
          </geometry>
      </visual>
      <collision>
          <geometry>
              <mesh filename="file://$(find panda_description)/meshes/collision/link7.stl" />
          </geometry>
      </collision>
    <inertial>
    <origin xyz="0 0 0.32"/>
    <mass value="0.5"/> 
    <inertia ixx="0.002" ixy="0" ixz="0" iyy="0.002" iyz="0" izz="0.002" />
    </inertial>
  </link>
  <joint name="panda_joint7" type="revolute">
      <safety_controller k_position="100.0" k_velocity="40.0" soft_lower_limit="-2.8973" soft_upper_limit="2.8973" />
      <origin rpy="1.57079632679 0 0" xyz="0.088 0 0" />
      <parent link="panda_link6" />
      <child link="panda_link7" />
      <axis xyz="0 0 1" />
      <limit effort="12" lower="-2.9671" upper="2.9671" velocity="2.8710" />
  </joint>
  <link name="panda_link8" />
  <joint name="panda_joint8" type="fixed">
      <origin rpy="0 0 0" xyz="0 0 0.107" />
      <parent link="panda_link7" />
      <child link="panda_link8" />
      <axis xyz="0 0 0" />
  </joint>
  <joint name="panda_hand_joint" type="fixed">
      <parent link="panda_link8" />
      <child link="panda_hand" />
      <origin rpy="0 0 -0.785398163397" xyz="0 0 0" />
  </joint>
  <link name="panda_hand">
      <visual>
          <geometry>
              <mesh filename="file://$(find panda_description)/meshes/visual/hand.dae" />
          </geometry>
      </visual>
      <collision>
          <geometry>
              <mesh filename="file://$(find panda_description)/meshes/collision/hand.stl" />
          </geometry>
      </collision>
    <inertial>
    <origin xyz="0 0 0.32"/>
    <mass value="0.5"/> 
    <inertia ixx="0.002" ixy="0" ixz="0" iyy="0.002" iyz="0" izz="0.002" />
    </inertial>
  </link>
  <link name="panda_leftfinger">
      <visual>
          <geometry>
              <mesh filename="file://$(find panda_description)/meshes/visual/finger.dae" />
          </geometry>
      </visual>
      <collision>
          <geometry>
              <mesh filename="file://$(find panda_description)/meshes/collision/finger.stl" />
          </geometry>
      </collision>
    <inertial>
    <origin xyz="0 0 0.32"/>
    <mass value="0.5"/> 
    <inertia ixx="0.002" ixy="0" ixz="0" iyy="0.002" iyz="0" izz="0.002" />
    </inertial>
  </link>
  <link name="panda_rightfinger">
      <visual>
          <origin rpy="0 0 3.14159265359" xyz="0 0 0" />
          <geometry>
              <mesh filename="file://$(find panda_description)/meshes/visual/finger.dae" />
          </geometry>
      </visual>
      <collision>
          <origin rpy="0 0 3.14159265359" xyz="0 0 0" />
          <geometry>
              <mesh filename="file://$(find panda_description)/meshes/collision/finger.stl" />
          </geometry>
      </collision>
    <inertial>
    <origin xyz="0 0 0.32"/>
    <mass value="0.5"/> 
    <inertia ixx="0.002" ixy="0" ixz="0" iyy="0.002" iyz="0" izz="0.002" />
    </inertial>
  </link>
  <joint name="panda_finger_joint1" type="prismatic">
      <parent link="panda_hand" />
      <child link="panda_leftfinger" />
      <origin rpy="0.0 0.0 0.0" xyz="0.0 0.0 0.0584" />
      <axis xyz="0 1 0" />
      <limit effort="40" lower="0.0" upper="0.04" velocity="0.2" />
  </joint>
  <joint name="panda_finger_joint2" type="prismatic">
      <parent link="panda_hand" />
      <child link="panda_rightfinger" />
      <origin rpy="0.0 0.0 0.0" xyz="0.0 0.0 0.0584" />
      <axis xyz="0 -1 0" />
      <limit effort="40" lower="0.0" upper="0.04" velocity="0.2" />
      <mimic joint="panda_finger_joint1" />
  </joint>
  
  <!-- https://github.com/ros-controls/gazebo_ros2_control/issues/173#issuecomment-1536332488 -->
  <joint name="panda_finger_joint2_mimic" type="fixed">
      <parent link="panda_hand" />
      <child link="random" />
  </joint>
  <link name="random"/>

  <!-- Camera -->
  <xacro:include filename="$(find panda_description)/urdf/camera/camera.xacro"/>
  <xacro:camera_v0 parent="panda_link0">
   <origin xyz="0.2 0.6 0.7" rpy="0 1.57 0"/>
  </xacro:camera_v0>
  
  <xacro:camera_gazebo_v0/>
  <!-- Camera -->


  <ros2_control name="GazeboSystem" type="system">
      <hardware>
          <plugin>gazebo_ros2_control/GazeboSystem</plugin>
      </hardware>
      <joint name="panda_joint1">
          <command_interface name="position">
              <param name="min">-1</param>
              <param name="max">1</param>
          </command_interface>
          <state_interface name="position">
              <param name="initial_value">0.0</param>
          </state_interface>
          <state_interface name="velocity"/>
      </joint>
      <joint name="panda_joint2">
          <command_interface name="position">
              <param name="min">-1</param>
              <param name="max">1</param>
          </command_interface>
          <state_interface name="position">
              <param name="initial_value">-0.789</param>
          </state_interface>
          <state_interface name="velocity"/>
      </joint>
      <joint name="panda_joint3">
          <command_interface name="position">
              <param name="min">-1</param>
              <param name="max">1</param>
          </command_interface>
          <state_interface name="position">
              <param name="initial_value">0.0</param>
          </state_interface>
          <state_interface name="velocity"/>
      </joint>
      <joint name="panda_joint4">
          <command_interface name="position">
              <param name="min">-1</param>
              <param name="max">1</param>
          </command_interface>
          <state_interface name="position">
              <param name="initial_value">-2.356</param>
          </state_interface>
          <state_interface name="velocity"/>
      </joint>
      <joint name="panda_joint5">
          <command_interface name="position">
              <param name="min">-1</param>
              <param name="max">1</param>
          </command_interface>
          <state_interface name="position">
              <param name="initial_value">0.0</param>
          </state_interface>
          <state_interface name="velocity"/>
      </joint>
      <joint name="panda_joint6">
          <command_interface name="position">
              <param name="min">-1</param>
              <param name="max">1</param>
          </command_interface>
          <state_interface name="position">
              <param name="initial_value">1.571</param>
          </state_interface>
          <state_interface name="velocity"/>
      </joint>
      <joint name="panda_joint7">
          <command_interface name="position">
              <param name="min">-1</param>
              <param name="max">1</param>
          </command_interface>
          <state_interface name="position">
              <param name="initial_value">0.785</param>
          </state_interface>
          <state_interface name="velocity"/>
      </joint>
        <joint name="panda_finger_joint1">
            <command_interface name="position" />
            <state_interface name="position">
                <param name="initial_value">0.0</param>
            </state_interface>
            <state_interface name="velocity">
                <param name="initial_value">0.0</param>
            </state_interface>
        </joint>
        <joint name="panda_finger_joint2">
            <param name="mimic">panda_finger_joint1</param>
            <param name="multiplier">1</param>
            <command_interface name="position" />
            <state_interface name="position">
                <param name="initial_value">0.0</param>
            </state_interface>
            <state_interface name="velocity">
                <param name="initial_value">0.0</param>
            </state_interface>
        </joint>
  </ros2_control>

  <!-- gazebo reference="camera_link"-->
  <gazebo>
    <plugin name="gazebo_ros2_control" filename="libgazebo_ros2_control.so">
        <parameters> $(find panda_gazebo)/config/ros2_controllers.yaml </parameters>
        <robot_param_node>robot_state_publisher</robot_param_node>
    </plugin>
    <!-- <plugin name="camera_controller" filename="libgazebo_ros_camera.so">
        <alwaysOn>true</alwaysOn>
        <updateRate>0.0</updateRate>
        <cameraName>panda/camera1</cameraName>
        <imageTopicName>image_raw</imageTopicName>
        <cameraInfoTopicName>camera_info</cameraInfoTopicName>
        <frameName>camera_link</frameName>
        <hackBaseline>0.07</hackBaseline>
    </plugin> -->

  </gazebo>
  <!-- <gazebo reference="camera_link">
    <plugin name="camera_controller" filename="libgazebo_ros_camera.so">
        <alwaysOn>true</alwaysOn>
        <updateRate>0.0</updateRate>
        <cameraName>panda/camera1</cameraName>
        <imageTopicName>image_raw</imageTopicName>
        <cameraInfoTopicName>camera_info</cameraInfoTopicName>
        <frameName>camera_link</frameName>
        <hackBaseline>0.07</hackBaseline>
        <distortionK1>0.0</distortionK1>
        <distortionK2>0.0</distortionK2>
        <distortionK3>0.0</distortionK3>
        <distortionT1>0.0</distortionT1>
        <distortionT2>0.0</distortionT2>
      </plugin>
  </gazebo> -->
    
</robot>
